Workbook

Sheet fantasycypherrs
A1: Fantasy Name | B1: Nom en Fantasy | C1: Cypher Name | D1: CSR Page | E1: Nom du Cypher | F1: Niveau | G1: Effet
A2: potion of climbing | B2: Potion d’escalade | C2: adhesion | D2: 384 | E2: =VLOOKUP(fantasycypherrs[[#This Row],[Cypher Name]],Sheet1!E:O,11,FALSE()) -> Adhésion | F2: =VLOOKUP(fantasycypherrs[[#This Row],[Cypher Name]],Sheet1!E:O,5,FALSE()) -> 1d6 | G2: =VLOOKUP(fantasycypherrs[[#This Row],[Cypher Name]],Sheet1!E:O,2,FALSE()) -> Permet de grimper automatiquement sur toute les surfaces, màême horizontales. Dure pendant 10 minutes par niveau du cypher.
A3: potion of longevity | B3: Potion de longévité | C3: age taker | D3: 384 | E3: =VLOOKUP(fantasycypherrs[[#This Row],[Cypher Name]],Sheet1!E:O,11,FALSE()) -> Preneur d'à‚ge | F3: =VLOOKUP(fantasycypherrs[[#This Row],[Cypher Name]],Sheet1!E:O,5,FALSE()) -> 1d6 + 4 | G3: =VLOOKUP(fantasycypherrs[[#This Row],[Cypher Name]],Sheet1!E:O,2,FALSE()) -> Commence un processus de rajeunissement qui enlève des années à l'âge physiologique du porteur. Au cours des sept prochains jours, le porteur perd un nombre d'années égal à trois fois le niveau du cypher. Le cypher ne ramène pas l'âge physiologique en dessous de vingt-trois ans.
A4: potion of soothed reflexes | B4: Potion de réflexes | C4: analeptic (level 3–4) | D4: 384 | E4: Analeptique (niveau 3-4) | F4: 1d6 + 2 | G4: Restaure un nombre de points égal au niveau du cypher dans la Réserve de Célérité de l'utilisateur.
A5: potion of greater soothed reflexes | B5: Potion de réflexes améliorée | C5: analeptic (level 5–6) | D5: 384 | E5: Analeptique (niveau 5-6) | F5: 1d6 + 2 | G5: Restaure un nombre de points égal au niveau du cypher dans la Réserve de Célérité de l'utilisateur.
A6: potion of superior soothed reflexes | B6: Potion de réflexes supérieure | C6: analeptic (level 7–8) | D6: 384 | E6: Analeptique (niveau 7-8) | F6: 1d6 + 2 | G6: Restaure un nombre de points égal au niveau du cypher dans la Réserve de Célérité de l'utilisateur.
A7: potion of vitality | B7: Potion de vitalité | C7: antivenom | D7: 384 | E7: =VLOOKUP(fantasycypherrs[[#This Row],[Cypher Name]],Sheet1!E:O,11,FALSE()) -> Antivenin | F7: =VLOOKUP(fantasycypherrs[[#This Row],[Cypher Name]],Sheet1!E:O,5,FALSE()) -> 1d6 + 2 | G7: =VLOOKUP(fantasycypherrs[[#This Row],[Cypher Name]],Sheet1!E:O,2,FALSE()) -> Rend l'utilisateur immunisé contre les poisons d'un niveau inférieur ou égal à celui du cypher pendant une heure par niveau du cypher (et annule tout effet en cours déjà présent dans le système de l'utilisateur).
A8: oil of armor enhancement | B8: Huile d’amélioration d’armure | C8: armor reinforcer | D8: 384 | E8: =VLOOKUP(fantasycypherrs[[#This Row],[Cypher Name]],Sheet1!E:O,11,FALSE()) -> Renforcement d'Armure | F8: =VLOOKUP(fantasycypherrs[[#This Row],[Cypher Name]],Sheet1!E:O,5,FALSE()) -> 1d6 + 1 | G8: =VLOOKUP(fantasycypherrs[[#This Row],[Cypher Name]],Sheet1!E:O,2,FALSE()) -> armure de l'utilisateur bénéficie d'une amélioration pendant vingt-quatre heures. Lancez un d6 pour déterminer le résultat.
A9: scroll of stealing | B9: Parchemin de larcin | C9: attractor | D9: 384 | E9: =VLOOKUP(fantasycypherrs[[#This Row],[Cypher Name]],Sheet1!E:O,11,FALSE()) -> Attracteur | F9: =VLOOKUP(fantasycypherrs[[#This Row],[Cypher Name]],Sheet1!E:O,5,FALSE()) -> 1d6 + 4 | G9: =VLOOKUP(fantasycypherrs[[#This Row],[Cypher Name]],Sheet1!E:O,2,FALSE()) -> Un objet non ancré de la taille de l'utilisateur ou plus petit, situé à longue portée (très longue portée si le niveau du cypher est de 8 ou plus), est immédiatement attiré vers l'utilisateur. Cela prend un tour. L'objet n'a aucun élan lorsqu'il arrive.
A10: oil of aggressive blinking | B10: Huile de clignotement agressif | C10: banishing | D10: 384 | E10: =VLOOKUP(fantasycypherrs[[#This Row],[Cypher Name]],Sheet1!E:O,11,FALSE()) -> Bannissement | F10: =VLOOKUP(fantasycypherrs[[#This Row],[Cypher Name]],Sheet1!E:O,5,FALSE()) -> 1d6 | G10: =VLOOKUP(fantasycypherrs[[#This Row],[Cypher Name]],Sheet1!E:O,2,FALSE()) -> Pendant la journée suivante, chaque fois que l'utilisateur frappe une créature ou un objet solide, cela génère une décharge d'énergie qui téléporte la créature ou l'objet à une distance immédiate dans une direction aléatoire (ni vers le haut ni vers le bas). Les actions de la créature téléportée (y compris la défense) sont entravées à son prochain tour (entravées de deux crans si le niveau du cypher est de 5 ou plus).
A11: carved bone of utility | B11: Os sculpté d’utilité | C11: best tool | D11: 384 | E11: =VLOOKUP(fantasycypherrs[[#This Row],[Cypher Name]],Sheet1!E:O,11,FALSE()) -> Meilleur Outil | F11: =VLOOKUP(fantasycypherrs[[#This Row],[Cypher Name]],Sheet1!E:O,5,FALSE()) -> 1d6 | G11: =VLOOKUP(fantasycypherrs[[#This Row],[Cypher Name]],Sheet1!E:O,2,FALSE()) -> Fournit un atout supplémentaire pour toute tâche utilisant un outil, màême si cela signifie dépasser la limite normale de deux atouts.
A12: scroll of nondetection | B12: Parchemin de non-détection | C12: blackout | D12: 384 | E12: =VLOOKUP(fantasycypherrs[[#This Row],[Cypher Name]],Sheet1!E:O,11,FALSE()) -> Blackout | F12: =VLOOKUP(fantasycypherrs[[#This Row],[Cypher Name]],Sheet1!E:O,5,FALSE()) -> 1d6 + 2 | G12: =VLOOKUP(fantasycypherrs[[#This Row],[Cypher Name]],Sheet1!E:O,2,FALSE()) -> Une zone à portée immédiate de l'utilisateur devient sécurisée contre tout effet extérieur à la zone qui tenterait de voir, d'entendre ou de percevoir ce qui se passe à l'intérieur. Pour les observateurs extérieurs, la zone apparaît comme un "flou" pour tout sens appliqué. Les écoutes, capteurs de divination et autres méthodes de surveillance directe sont également rendus inopérants dans la zone pendant une journée.
A13: oil of defensive blinking | B13: Huile de clignotement défensif | C13: blinking | D13: 385 | E13: =VLOOKUP(fantasycypherrs[[#This Row],[Cypher Name]],Sheet1!E:O,11,FALSE()) -> Clignotement | F13: =VLOOKUP(fantasycypherrs[[#This Row],[Cypher Name]],Sheet1!E:O,5,FALSE()) -> 1d6 | G13: =VLOOKUP(fantasycypherrs[[#This Row],[Cypher Name]],Sheet1!E:O,2,FALSE()) -> Pendant la journée suivante, chaque fois que l'utilisateur est frappé suffisamment fort pour subir des dégâts (mais pas plus d'une fois par tour), il se téléporte à une distance immédiate dans une direction aléatoire (ni vers le haut ni vers le bas). Comme l'utilisateur est préparé à cet effet et que son adversaire ne l'est pas, les défenses de l'utilisateur sont facilitées pendant un tour après la téléportation.
A14: potion of longstrider | B14: Potion de grand-pas | C14: burst of speed | D14: 385 | E14: =VLOOKUP(fantasycypherrs[[#This Row],[Cypher Name]],Sheet1!E:O,11,FALSE()) -> Explosion de Célérité | F14: =VLOOKUP(fantasycypherrs[[#This Row],[Cypher Name]],Sheet1!E:O,5,FALSE()) -> 1d6 | G14: =VLOOKUP(fantasycypherrs[[#This Row],[Cypher Name]],Sheet1!E:O,2,FALSE()) -> Pendant une minute, un utilisateur qui peut normalement se déplacer sur une courte distance en une action peut se déplacer sur une longue distance à la place.
A15: potion of cure disease | B15: Potion de guérison des maladies | C15: catholicon | D15: 385 | E15: =VLOOKUP(fantasycypherrs[[#This Row],[Cypher Name]],Sheet1!E:O,11,FALSE()) -> Catholicon | F15: =VLOOKUP(fantasycypherrs[[#This Row],[Cypher Name]],Sheet1!E:O,5,FALSE()) -> 1d6 + 2 | G15: =VLOOKUP(fantasycypherrs[[#This Row],[Cypher Name]],Sheet1!E:O,2,FALSE()) -> Guérit toute maladie d'un niveau égal ou inférieur à celui du cypher.
A16: potion of magical sorrows | B16: Potion des sanglots magiques | C16: chemical factory | D16: 385 | E16: =VLOOKUP(fantasycypherrs[[#This Row],[Cypher Name]],Sheet1!E:O,11,FALSE()) -> Usine Chimique | F16: =VLOOKUP(fantasycypherrs[[#This Row],[Cypher Name]],Sheet1!E:O,5,FALSE()) -> 1d6 | G16: =VLOOKUP(fantasycypherrs[[#This Row],[Cypher Name]],Sheet1!E:O,2,FALSE()) -> Après une heure, la sueur de l'utilisateur produit 1d6 doses d'un liquide précieux (ces doses ne sont pas considérées comme des cyphers). Elles doivent àêtre utilisées dans la semaine. Lancez un d100 pour déterminer l'effet.
A17: scroll of message | B17: Parchemin de message | C17: Psychic communique | D17: 395 | E17: =VLOOKUP(fantasycypherrs[[#This Row],[Cypher Name]],Sheet1!E:O,11,FALSE()) -> Communication Psychique | F17: =VLOOKUP(fantasycypherrs[[#This Row],[Cypher Name]],Sheet1!E:O,5,FALSE()) -> 1d6 + 2 | G17: =VLOOKUP(fantasycypherrs[[#This Row],[Cypher Name]],Sheet1!E:O,2,FALSE()) -> Permet à l'utilisateur de projeter un message télépathique unique et unidirectionnel de jusqu'à dix mots par niveau de cypher, avec une portée illimitée, à quiconque qu'il connaît.
A18: potion of language comprehension | B18: Potion de compréhension des langues | C18: comprehension | D18: 385 | E18: =VLOOKUP(fantasycypherrs[[#This Row],[Cypher Name]],Sheet1!E:O,11,FALSE()) -> Compréhension | F18: =VLOOKUP(fantasycypherrs[[#This Row],[Cypher Name]],Sheet1!E:O,5,FALSE()) -> 1d6 + 1 | G18: =VLOOKUP(fantasycypherrs[[#This Row],[Cypher Name]],Sheet1!E:O,2,FALSE()) -> En cinq minutes, l'utilisateur peut comprendre les mots d'une langue spécifique liée au cypher (deux langues si le cypher est de niveau 5 ou plus). Cela est vrai màême pour les créatures qui ne possèdent normalement pas de langage. Si l'utilisateur comprenait déjà la langue, le cypher n'a aucun effet. Une fois utilisé, l'effet est permanent et le cypher ne compte plus dans la limite de cyphers qu'un personnage peut porter.
... A21: oil of controlled blinking | B21: Huile de clignotement contrôlé | C21: controlled blinking | D21: 386 | E21: =VLOOKUP(fantasycypherrs[[#This Row],[Cypher Name]],Sheet1!E:O,11,FALSE()) -> Clignotement Contrôlé | F21: =VLOOKUP(fantasycypherrs[[#This Row],[Cypher Name]],Sheet1!E:O,5,FALSE()) -> 1d6 + 2 | G21: =VLOOKUP(fantasycypherrs[[#This Row],[Cypher Name]],Sheet1!E:O,2,FALSE()) -> Pendant la journée suivante, chaque fois que l'utilisateur est frappé suffisamment fort pour subir des dégâts (mais pas plus d'une fois par tour), il se téléporte à un endroit de son choix à portée immédiate. Comme il est préparé à cet effet et que son adversaire ne l'est pas, les défenses de l'utilisateur sont facilitées pendant un tour après la téléportation.
A22: potion of healing | B22: Potion de soin | C22: curative (level 3–4) | D22: 386 | E22: Curatif (niveau 3-4) | F22: 1d6 + 2 | G22: Restaure un nombre de points égal au niveau du cypher dans la Réserve de Puissance de l'utilisateur.
A23: potion of greater healing | B23: Potion de soin améliorée | C23: curative (level 5–6) | D23: 386 | E23: Curatif (niveau 5-6) | F23: 1d6 + 2 | G23: Restaure un nombre de points égal au niveau du cypher dans la Réserve de Puissance de l'utilisateur.
A24: potion of superior healing | B24: Potion de soin supérieure | C24: curative (level 7–8) | D24: 386 | E24: Curatif (niveau 7-8) | F24: 1d6 + 2 | G24: Restaure un nombre de points égal au niveau du cypher dans la Réserve de Puissance de l'utilisateur.
A25: scroll of the unexpected curse | B25: Parchemin de maladie | C25: curse bringer | D25: 386 | E25: =VLOOKUP(fantasycypherrs[[#This Row],[Cypher Name]],Sheet1!E:O,11,FALSE()) -> Porteur de Malédiction | F25: =VLOOKUP(fantasycypherrs[[#This Row],[Cypher Name]],Sheet1!E:O,5,FALSE()) -> 1d6 + 1 | G25: =VLOOKUP(fantasycypherrs[[#This Row],[Cypher Name]],Sheet1!E:O,2,FALSE()) -> Le cypher peut àêtre activé lorsqu'il est donné à une personne qui n'en connaît pas l'importance. La prochaine fois que la victime tente une tâche importante alors qu'elle est en possession du cypher, la tâche est entravée de trois crans.
A26: potion of darksight | B26: Potion de vision nocturne | C26: darksight | D26: 386 | E26: =VLOOKUP(fantasycypherrs[[#This Row],[Cypher Name]],Sheet1!E:O,11,FALSE()) -> Vision Nocturne | F26: =VLOOKUP(fantasycypherrs[[#This Row],[Cypher Name]],Sheet1!E:O,5,FALSE()) -> 1d6 | G26: =VLOOKUP(fantasycypherrs[[#This Row],[Cypher Name]],Sheet1!E:O,2,FALSE()) -> Confère la capacité de voir dans le noir pendant cinq heures par niveau du cypher. (Pour un jeu plus réaliste, ce cypher pourrait plutôt rendre l'utilisateur spécialisé dans la détection en faible luminosité.)
A27: death bringer rune | B27: Rune de mort | C27: death bringer | D27: 386 | E27: =VLOOKUP(fantasycypherrs[[#This Row],[Cypher Name]],Sheet1!E:O,11,FALSE()) -> Porteur de Mort | F27: =VLOOKUP(fantasycypherrs[[#This Row],[Cypher Name]],Sheet1!E:O,5,FALSE()) -> 1d6 | G27: =VLOOKUP(fantasycypherrs[[#This Row],[Cypher Name]],Sheet1!E:O,2,FALSE()) -> Pendant la prochaine minute, lorsque l'utilisateur frappe un PNJ ou une créature d'un niveau égal ou inférieur à celui du cypher, il peut choisir de faire un second jet d'attaque. Si ce second jet d'attaque est une réussite, la cible est tuée. Si la cible est un PJ, le personnage descend d'un cran sur la piste de dégâts.
A28: oil of dense strikes | B28: Huile de frappe forte | C28: density | D28: 386 | E28: =VLOOKUP(fantasycypherrs[[#This Row],[Cypher Name]],Sheet1!E:O,11,FALSE()) -> Densité | F28: =VLOOKUP(fantasycypherrs[[#This Row],[Cypher Name]],Sheet1!E:O,5,FALSE()) -> 1d6 | G28: =VLOOKUP(fantasycypherrs[[#This Row],[Cypher Name]],Sheet1!E:O,2,FALSE()) -> Pendant la journée suivante, chaque fois que l'utilisateur frappe une créature ou un objet solide avec une arme, l'arme voit soudainement son poids augmenter de manière spectaculaire, ce qui inflige 2 points de dégâts supplémentaires.
A29: scroll of fleshbane burst | B29: Parchemin d’explosion nécrotique | C29: detonation (cell-disrupting) | D29: 386 | E29: Détonation (nécrose des chairs) | F29: 1d6 + 2 | G29: Projette un petit explosif physique jusqu'à longue distance qui explose dans un rayon immédiat, infligeant des dégâts égaux au niveau du cypher.
A30: scroll of frost burst | B30: Parchemin d’explosion de froid | C30: detonation (cold) | D30: 386 | E30: Détonation (froid) | F30: 1d6 + 2 | G30: Projette un petit explosif physique jusqu'à longue distance qui explose dans un rayon immédiat, infligeant des dégâts égaux au niveau du cypher.
A31: scroll of acid burst | B31: Parchemin d’explosion d’acide | C31: detonation (corrosive) | D31: 386 | E31: Détonation (Corrosif) | F31: 1d6 + 2 | G31: Projette un petit explosif physique jusqu'à longue distance qui explose dans un rayon immédiat, infligeant des dégâts égaux au niveau du cypher.
A32: gem of monster summoning | B32: Gemme d’invocation de monstre | C32: detonation (creature) | D32: 386 | E32: =VLOOKUP(fantasycypherrs[[#This Row],[Cypher Name]],Sheet1!E:O,11,FALSE()) -> Détonation (Créature) | F32: =VLOOKUP(fantasycypherrs[[#This Row],[Cypher Name]],Sheet1!E:O,5,FALSE()) -> 1d6 + 1 | G32: =VLOOKUP(fantasycypherrs[[#This Row],[Cypher Name]],Sheet1!E:O,2,FALSE()) -> Projette un petit explosif physique jusqu'à longue distance qui explose et crée un portail de téléportation temporaire. Une créature aléatoire dont le niveau est inférieur ou égal à celui du cypher apparaît à travers le portail et attaque la cible la plus proche. Au bout d'environ une minute, la créature disparaît.
A33: scroll of withering burst | B33: Parchemin d’explosion desséchante | C33: detonation (desiccating) | D33: 386 | E33: =VLOOKUP(fantasycypherrs[[#This Row],[Cypher Name]],Sheet1!E:O,11,FALSE()) -> Détonation (Desséchant) | F33: =VLOOKUP(fantasycypherrs[[#This Row],[Cypher Name]],Sheet1!E:O,5,FALSE()) -> 1d6 + 2 | G33: =VLOOKUP(fantasycypherrs[[#This Row],[Cypher Name]],Sheet1!E:O,2,FALSE()) -> Projette un petit explosif physique jusqu'à longue distance qui éclate dans un rayon immédiat, drainant l'humidité de tout ce qui s'y trouve. Les créatures vivantes subissent des dégâts égaux au niveau du cypher. L'eau présente dans la zone est vaporisée.
A34: scroll of lightning burst | B34: Parchemin d’explosion électrique | C34: detonation (electrical discharge) | D34: 386 | E34: Détonation (électrique) | F34: 1d6 + 2 | G34: Projette un petit explosif physique jusqu'à longue distance qui explose dans un rayon immédiat, infligeant des dégâts égaux au niveau du cypher.
A35: scroll of flame burst | B35: Parchemin d’explosion de feu | C35: detonation (fire) | D35: 386 | E35: Détonation (feu) | F35: 1d6 + 2 | G35: Projette un petit explosif physique jusqu'à longue distance qui explose dans un rayon immédiat, infligeant des dégâts de feu égaux au niveau du cypher.
A36: scroll of blindness | B36: Parchemin de cécité | C36: detonation (flash) | D36: 386 | E36: =VLOOKUP(fantasycypherrs[[#This Row],[Cypher Name]],Sheet1!E:O,11,FALSE()) -> Détonation (Flash) | F36: =VLOOKUP(fantasycypherrs[[#This Row],[Cypher Name]],Sheet1!E:O,5,FALSE()) -> 1d6 + 2 | G36: =VLOOKUP(fantasycypherrs[[#This Row],[Cypher Name]],Sheet1!E:O,2,FALSE()) -> Projette un petit explosif physique jusqu'à longue distance qui éclate dans un rayon immédiat, aveuglant tous ceux qui s'y trouvent pendant une minute (dix minutes si le cypher est de niveau 4 ou plus).
A37: scroll of reverse gravity | B37: Parchemin d’inversion de la gravité | C37: detonation (gravity inversion) | D37: 387 | E37: =VLOOKUP(fantasycypherrs[[#This Row],[Cypher Name]],Sheet1!E:O,11,FALSE()) -> Détonation (Inversion Gravitationnelle) | F37: =VLOOKUP(fantasycypherrs[[#This Row],[Cypher Name]],Sheet1!E:O,5,FALSE()) -> 1d6 + 1 | G37: =VLOOKUP(fantasycypherrs[[#This Row],[Cypher Name]],Sheet1!E:O,2,FALSE()) -> Projette un petit explosif physique jusqu'à longue distance qui explose, et pendant une heure, la gravité est inversée dans un rayon long autour de l'explosion.
A38: scroll of invisible weights | B38: Parchemin des poids invisibles | C38: detonation (gravity) | D38: 387 | E38: =VLOOKUP(fantasycypherrs[[#This Row],[Cypher Name]],Sheet1!E:O,11,FALSE()) -> Détonation (Gravité) | F38: =VLOOKUP(fantasycypherrs[[#This Row],[Cypher Name]],Sheet1!E:O,5,FALSE()) -> 1d6 + 2 | G38: =VLOOKUP(fantasycypherrs[[#This Row],[Cypher Name]],Sheet1!E:O,2,FALSE()) -> ProjetteDetonation (Gravity) un petit explosif physique jusqu'à longue distance qui éclate dans un rayon immédiat, infligeant des dégâts égaux au niveau du cypher en augmentant fortement la gravité pendant une seconde. Toutes les créatures dans la zone sont écrasées au sol pendant un tour et ne peuvent pas effectuer d'actions physiques.
A39: scroll of enlarged fleshbane burst | B39: Parchemin d’explosion nécrotique étendue | C39: detonation (massive,cell-disrupting) | D39: 387 | E39: Détonation (Massive, nécrose des chairs) | F39: 1d6 + 2 | G39: Projette un petit explosif physique jusqu'à longue distance qui explose dans un rayon de courte portée, infligeant des dégâts de nécrose des chairs égaux au niveau du cypher.
A40: scroll of enlarged frost burst | B40: Parchemin d’explosion de froid étendue | C40: detonation (massive,cold) | D40: 387 | E40: Détonation (Massive, froid) | F40: 1d6 + 2 | G40: Projette un petit explosif physique jusqu'à longue distance qui explose dans un rayon de courte portée, infligeant des dégâts de froid égaux au niveau du cypher.
A41: scroll of enlarged acid burst | B41: Parchemin d’explosion d’acide étendue | C41: detonation (massive,corrosive) | D41: 387 | E41: Détonation (Massive, corrosif) | F41: 1d6 + 2 | G41: Projette un petit explosif physique jusqu'à longue distance qui explose dans un rayon immédiat, infligeant des dégâts corrosifs égaux au niveau du cypher.
A42: scroll of enlarged lightning burst | B42: Parchemin d’explosion électrique étendue | C42: detonation (massive,electrical discharge) | D42: 387 | E42: Détonation (Massive, électrique) | F42: 1d6 + 2 | G42: Projette un petit explosif physique jusqu'à longue distance qui explose dans un rayon de courte portée, infligeant des dégâts électriques égaux au niveau du cypher.
...

Sheet Sheet1
A1: pub_date | B1: created | C1: updated | D1: name | E1: name_en | F1: effect | G1: hint | H1: table | I1: level | J1: cs_page | K1: is_manifeste | L1: is_fantastic | M1: is_subtle | N1: Column1 | O1: Column2
A2: 2024-10-01T16:53:31.844Z | B2: 2024-10-01T16:53:31.844Z | C2: 2024-10-01T16:53:31.844Z | D2: Stimulant | E2: Stim | F2: Facilite la prochaine action de l'utilisateur de trois crans. | I2: 1d6 | J2: (Cypher System Rulebook, page 398) | K2: =FALSE() -> FALSE | L2: =FALSE() -> FALSE | M2: =TRUE() -> TRUE | N2: =LEN(Table1[[#This Row],[effect]]) -> 61 | O2: =Table1[[#This Row],[name]] -> Stimulant
A3: 2024-10-01T16:53:31.483Z | B3: 2024-10-01T16:53:31.483Z | C3: 2024-10-01T16:53:31.483Z | D3: Stabilisateur Mental | E3: Mind Stabilizer | F3: L'utilisateur gagne +5 à l'Armure contre les dégâts d'Intellect. | I3: 1d6 | J3: (Cypher System Rulebook, page 393) | K3: =FALSE() -> FALSE | L3: =FALSE() -> FALSE | M3: =TRUE() -> TRUE | N3: =LEN(Table1[[#This Row],[effect]]) -> 65 | O3: =Table1[[#This Row],[name]] -> Stabilisateur Mental
A4: 2024-10-01T16:53:30.915Z | B4: 2024-10-01T16:53:30.915Z | C4: 2024-10-01T16:53:30.915Z | D4: Catholicon | E4: Catholicon | F4: Guérit toute maladie d'un niveau égal ou inférieur à celui du cypher. | I4: 1d6 + 2 | J4: (Cypher System Rulebook, page 385) | K4: =TRUE() -> TRUE | L4: =FALSE() -> FALSE | M4: =FALSE() -> FALSE | N4: =LEN(Table1[[#This Row],[effect]]) -> 70 | O4: =Table1[[#This Row],[name]] -> Catholicon
A5: 2024-10-01T16:53:31.528Z | B5: 2024-10-01T16:53:31.528Z | C5: 2024-10-01T16:53:31.528Z | D5: Perfection | E5: Perfection | F5: L'utilisateur considère sa prochaine action comme s'il avait lancé un naturel 20. | I5: 1d6 + 2 | J5: (Cypher System Rulebook, page 393) | K5: =TRUE() -> TRUE | L5: =FALSE() -> FALSE | M5: =TRUE() -> TRUE | N5: =LEN(Table1[[#This Row],[effect]]) -> 81 | O5: =Table1[[#This Row],[name]] -> Perfection
A6: 2024-10-01T16:53:31.676Z | B6: 2024-10-01T16:53:31.676Z | C6: 2024-10-01T16:53:31.676Z | D6: Régénérateur | E6: Rejuvenator | F6: Restaure un nombre de points égal au niveau du cypher à une Réserve de stat aléatoire. | H6: <table class="table table-light table-striped table-sm og-dt"> <thead> <tr> <th scope="col" class="text-center w-15">d100</th> <th>Stat Pool</th> </tr> </thead> <tbody> <tr> <td scope="col" class="text-center w-15">01&mdash;50</td> <td>Réserve de Puissance</td> </tr> <tr> <td scope="col" class="text-center w-15">51&mdash;75</td> <td>Réserve de Célérité</td> </tr> <tr> <td scope="col" class="text-center w-15">76&mdash;00</td> <td>Réserve d'Intellect</td> </tr> </tbody> </table> | I6: 1d6 + 2 | J6: (Cypher System Rulebook, page 395) | K6: =FALSE() -> FALSE | L6: =FALSE() -> FALSE | M6: =TRUE() -> TRUE | N6: =LEN(Table1[[#This Row],[effect]]) -> 87 | O6: =Table1[[#This Row],[name]] -> Régénérateur
A7: 2024-10-01T16:53:31.429Z | B7: 2024-10-01T16:53:31.429Z | C7: 2024-10-01T16:53:31.429Z | D7: Aide à la Méditation | E7: Meditation Aid | F7: Restaure un nombre de points égal au niveau du cypher à la Réserve d'Intellect de l'utilisateur. | I7: 1d6 + 2 | J7: (Cypher System Rulebook, page 392) | K7: =FALSE() -> FALSE | L7: =FALSE() -> FALSE | M7: =TRUE() -> TRUE | N7: =LEN(Table1[[#This Row],[effect]]) -> 97 | O7: =Table1[[#This Row],[name]] -> Aide à la Méditation
A8: 2024-10-01T16:53:32.019Z | B8: 2024-10-01T16:53:32.019Z | C8: 2024-10-01T16:53:32.019Z | D8: Ailes | E8: Wings | F8: L'utilisateur peut voler à sa vitesse de course normale pendant dix minutes par niveau de cypher. | I8: 1d6 + 2 | J8: (Cypher System Rulebook, page 400) | K8: =TRUE() -> TRUE | L8: =TRUE() -> TRUE | M8: =FALSE() -> FALSE | N8: =LEN(Table1[[#This Row],[effect]]) -> 98 | O8: =Table1[[#This Row],[name]] -> Ailes
A9: 2024-10-01T16:53:30.845Z | B9: 2024-10-01T16:53:30.845Z | C9: 2024-10-01T16:53:30.845Z | D9: Analeptique | E9: Analeptic | F9: Restaure un nombre de points égal au niveau du cypher dans la Réserve de Célérité de l'utilisateur. | I9: 1d6 + 2 | J9: (Cypher System Rulebook, page 384) | K9: =FALSE() -> FALSE | L9: =FALSE() -> FALSE | M9: =TRUE() -> TRUE | N9: =LEN(Table1[[#This Row],[effect]]) -> 99 | O9: =Table1[[#This Row],[name]] -> Analeptique
A10: 2024-10-01T16:53:31.169Z | B10: 2024-10-01T16:53:31.169Z | C10: 2024-10-01T16:53:31.169Z | D10: Bouclier Durable | E10: Enduring Shield | F10: Pour la prochaine journée, l'utilisateur bénéficie d'un atout pour les jets de défense en Célérité. | I10: 1d6 + 4 | J10: (Cypher System Rulebook, page 388) | K10: =FALSE() -> FALSE | L10: =FALSE() -> FALSE | M10: =TRUE() -> TRUE | N10: =LEN(Table1[[#This Row],[effect]]) -> 99 | O10: =Table1[[#This Row],[name]] -> Bouclier Durable
A11: 2024-10-01T16:53:30.959Z | B11: 2024-10-01T16:53:30.959Z | C11: 2024-10-01T16:53:30.959Z | D11: Curatif | E11: Curative | F11: Restaure un nombre de points égal au niveau du cypher dans la Réserve de Puissance de l'utilisateur. | I11: 1d6 + 2 | J11: (Cypher System Rulebook, page 386) | K11: =TRUE() -> TRUE | L11: =FALSE() -> FALSE | M11: =TRUE() -> TRUE | N11: =LEN(Table1[[#This Row],[effect]]) -> 100 | O11: =Table1[[#This Row],[name]] -> Curatif
A12: 2024-10-01T16:53:31.547Z | B12: 2024-10-01T16:53:31.547Z | C12: 2024-10-01T16:53:31.547Z | D12: Poison (Emotion) | E12: Poison (Emotion) | F12: La victime ressent une émotion spécifique pendant une heure. Lancez un d100 pour déterminer l'émotion. | G12: ===== <table class="table table-light table-striped table-sm og-dt"> <thead> <tr> <th scope="col" class="text-center w-15">d100</th> <th>Emotion</th> </tr> </thead> <tbody> <tr> <td scope="col" class="text-center w-15">01&mdash;20</td> <td>Colère. Pràêt à attaquer quiconque n'est pas d'accord avec eux. Très difficile à interagir ; toutes ces actions sont entravées de deux étapes.</td> </tr> <tr> <td scope="col" class="text-center w-15">21&mdash;40</td> <td>Peur. Fuit dans la terreur pendant une minute lorsqu'il est menacé.</td> </tr> <tr> <td scope="col" class="text-center w-15">41&mdash;60</td> <td>Désir. Ne peut se concentrer sur aucune activité non sexuelle.</td> </tr> <tr> <td scope="col" class="text-center w-15">61&mdash;75</td> <td>Tristesse. Toutes les tâches sont entravées.</td> </tr> <tr> <td scope="col" class="text-center w-15">76&mdash;85</td> <td>Complaisance. N'a aucune motivation. Toutes les tâches sont entravées de deux étapes.</td> </tr> <tr> <td scope="col" class="text-center w-15">86&mdash;95</td> <td>Joie. Facile à interagir de manière agréable ; toutes les tâches d'interaction agréables sont facilitées.</td> </tr> <tr> <td scope="col" class="text-center w-15">96&mdash;00</td> <td>Amour. Beaucoup plus facile à interagir ; toutes les tâches d'interaction sont facilitées de deux étapes, mais un attachement temporaire est probable.</td> </tr> </tbody> </table> ===== | H12: <table class="table table-light table-striped table-sm og-dt"> <thead> <tr> <th scope="col" class="text-center w-15">d100</th> <th>Emotion</th> </tr> </thead> <tbody> <tr> <td scope="col" class="text-center w-15">01&mdash;20</td> <td>Colère. Pràêt à attaquer quiconque n'est pas d'accord avec eux. Très difficile à interagir ; toutes ces actions sont entravées de deux étapes.</td> </tr> <tr> <td scope="col" class="text-center w-15">21&mdash;40</td> <td>Peur. Fuit dans la terreur pendant une minute lorsqu'il est menacé.</td> </tr> <tr> <td scope="col" class="text-center w-15">41&mdash;60</td> <td>Désir. Ne peut se concentrer sur aucune activité non sexuelle.</td> </tr> <tr> <td scope="col" class="text-center w-15">61&mdash;75</td> <td>Tristesse. Toutes les tâches sont entravées.</td> </tr> <tr> <td scope="col" class="text-center w-15">76&mdash;85</td> <td>Complaisance. N'a aucune motivation. Toutes les tâches sont entravées de deux étapes.</td> </tr> <tr> <td scope="col" class="text-center w-15">86&mdash;95</td> <td>Joie. Facile à interagir de manière agréable ; toutes les tâches d'interaction agréables sont facilitées.</td> </tr> <tr> <td scope="col" class="text-center w-15">96&mdash;00</td> <td>Amour. Beaucoup plus facile à interagir ; toutes les tâches d'interaction sont facilitées de deux étapes, mais un attachement temporaire est probable.</td> </tr> </tbody> </table> | I12: 1d6 + 2 | J12: (Cypher System Rulebook, page 394) | K12: =TRUE() -> TRUE | L12: =FALSE() -> FALSE | M12: =FALSE() -> FALSE | N12: =LEN(Table1[[#This Row],[effect]]) -> 102 | O12: =Table1[[#This Row],[name]] -> Poison (Emotion)
A13: 2024-10-01T16:53:31.851Z | B13: 2024-10-01T16:53:31.851Z | C13: 2024-10-01T16:53:31.851Z | D13: Amélioration de Puissance | E13: Strength Boost | F13: Ajoute 1 à l'Avantage de Puissance pendant une heure (ou 2 si le cypher est de niveau 5 ou supérieur). | I13: 1d6 + 2 | J13: (Cypher System Rulebook, page 398) | K13: =FALSE() -> FALSE | L13: =FALSE() -> FALSE | M13: =TRUE() -> TRUE | N13: =LEN(Table1[[#This Row],[effect]]) -> 103 | O13: =Table1[[#This Row],[name]] -> Amélioration de Puissance
A14: 2024-10-01T16:53:31.107Z | B14: 2024-10-01T16:53:31.107Z | C14: 2024-10-01T16:53:31.107Z | D14: Désarmement | E14: Disarm | F14: Un PNJ dans un rayon immédiat dont le niveau est inférieur à celui du cypher laisse tomber ce qu'il tient. | I14: 1d6 + 1 | J14: (Cypher System Rulebook, page 387) | K14: =FALSE() -> FALSE | L14: =FALSE() -> FALSE | M14: =TRUE() -> TRUE | N14: =LEN(Table1[[#This Row],[effect]]) -> 107 | O14: =Table1[[#This Row],[name]] -> Désarmement
A15: 2024-10-01T16:53:31.792Z | B15: 2024-10-01T16:53:31.792Z | C15: 2024-10-01T16:53:31.792Z | D15: Solvant | E15: Solvent | F15: Dissout 1 pied cube de matériel chaque round. Après un round par niveau de cypher, le cypher devient inerte. | I15: 1d10 | J15: (Cypher System Rulebook, page 397) | K15: =TRUE() -> TRUE | L15: =FALSE() -> FALSE | M15: =FALSE() -> FALSE | N15: =LEN(Table1[[#This Row],[effect]]) -> 108 | O15: =Table1[[#This Row],[name]] -> Solvant
A16: 2024-10-01T16:53:31.348Z | B16: 2024-10-01T16:53:31.348Z | C16: 2024-10-01T16:53:31.348Z | D16: Amplificateur d'Intellect | E16: Intellect Booster | F16: Ajoute 1 à l'Avantage d'Intellect de l'utilisateur pendant une heure (ou 2 si le cypher est de niveau 5 ou plus). | I16: 1d6 + 2 | J16: (Cypher System Rulebook, page 391) | K16: =FALSE() -> FALSE | L16: =FALSE() -> FALSE | M16: =TRUE() -> TRUE | N16: =LEN(Table1[[#This Row],[effect]]) -> 114 | O16: =Table1[[#This Row],[name]] -> Amplificateur d'Intellect
A17: 2024-10-01T16:53:30.860Z | B17: 2024-10-01T16:53:30.860Z | C17: 2024-10-01T16:53:30.860Z | D17: Renforcement d'Armure | E17: Armor Reinforcer | F17: armure de l'utilisateur bénéficie d'une amélioration pendant vingt-quatre heures. Lancez un d6 pour déterminer le résultat. | H17: <table class="table table-light table-striped table-sm og-dt"> <thead> <tr> <th>d6</th> <th>Bonus d'Armure</th> </tr> </thead> <tbody> <tr> <td scope="col" class="text-center w-15">1</td> <td>+1 à l'Armure</td> </tr> <tr> <td scope="col" class="text-center w-15">2</td> <td>+2 à l'Armure</td> </tr> <tr> <td scope="col" class="text-center w-15">3</td> <td>+3 à l'Armure</td> </tr> <tr> <td scope="col" class="text-center w-15">4</td> <td>+2 à l'Armure, +5 contre les dégâts de feu</td> </tr> <tr> <td scope="col" class="text-center w-15">5</td> <td>+2 à l'Armure, +5 contre les dégâts de froid</td> </tr> <tr> <td scope="col" class="text-center w-15">6</td> <td>+2 à l'Armure, +5 contre les dégâts d'acide</td> </tr> </tbody> </table> | I17: 1d6 + 1 | J17: (Cypher System Rulebook, page 384) | K17: =TRUE() -> TRUE | L17: =FALSE() -> FALSE | M17: =FALSE() -> FALSE | N17: =LEN(Table1[[#This Row],[effect]]) -> 123 | O17: =Table1[[#This Row],[name]] -> Renforcement d'Armure
A18: 2024-10-01T16:53:30.835Z | B18: 2024-10-01T16:53:30.835Z | C18: 2024-10-01T16:53:30.835Z | D18: Adhésion | E18: Adhesion | F18: Permet de grimper automatiquement sur toute les surfaces, màême horizontales. Dure pendant 10 minutes par niveau du cypher. | I18: 1d6 | J18: (Cypher System Rulebook, page 384) | K18: =TRUE() -> TRUE | L18: =FALSE() -> FALSE | M18: =FALSE() -> FALSE | N18: =LEN(Table1[[#This Row],[effect]]) -> 123 | O18: =Table1[[#This Row],[name]] -> Adhésion
A19: 2024-10-01T16:53:31.821Z | B19: 2024-10-01T16:53:31.821Z | C19: 2024-10-01T16:53:31.821Z | D19: Amélioration de Célérité | E19: Speed Boost | F19: Ajoute 1 à l'Avantage de Célérité de l'utilisateur pendant une heure (ajoute 2 si le cypher est de niveau 5 ou supérieur). | I19: 1d6 + 2 | J19: (Cypher System Rulebook, page 398) | K19: =FALSE() -> FALSE | L19: =FALSE() -> FALSE | M19: =FALSE() -> FALSE | N19: =LEN(Table1[[#This Row],[effect]]) -> 123 | O19: =Table1[[#This Row],[name]] -> Amélioration de Célérité
A20: 2024-10-01T16:53:31.518Z | B20: 2024-10-01T16:53:31.518Z | C20: 2024-10-01T16:53:31.518Z | D20: Nutrition et Hydratation | E20: Nutrition And Hydration | F20: L'utilisateur peut se passer de nourriture et d'eau pendant un nombre de jours égal au niveau du cypher sans effets néfastes. | I20: 1d6 + 1 | J20: (Cypher System Rulebook, page 393) | K20: =FALSE() -> FALSE | L20: =FALSE() -> FALSE | M20: =TRUE() -> TRUE | N20: =LEN(Table1[[#This Row],[effect]]) -> 125 | O20: =Table1[[#This Row],[name]] -> Nutrition et Hydratation
A21: 2024-10-01T16:53:31.753Z | B21: 2024-10-01T16:53:31.753Z | C21: 2024-10-01T16:53:31.753Z | D21: Electrisant | E21: Shocker | F21: Inflige une puissante décharge d'électricité qui choque toute créature touchée, infligeant des dégâts égaux au niveau du cyphe | I21: 1d6 + 4 | J21: (Cypher System Rulebook, page 396) | K21: =TRUE() -> TRUE | L21: =FALSE() -> FALSE | M21: =FALSE() -> FALSE | N21: =LEN(Table1[[#This Row],[effect]]) -> 126 | O21: =Table1[[#This Row],[name]] -> Electrisant
A22: 2024-10-01T16:53:31.876Z | B22: 2024-10-01T16:53:31.876Z | C22: 2024-10-01T16:53:31.876Z | D22: Télépathie | E22: Telepathy | F22: Pendant une heure, le dispositif permet une communication mentale à longue distance avec quiconque que l'utilisateur peut voir. | I22: 1d6 + 2 | J22: (Cypher System Rulebook, page 398) | K22: =TRUE() -> TRUE | L22: =TRUE() -> TRUE | M22: =FALSE() -> FALSE | N22: =LEN(Table1[[#This Row],[effect]]) -> 128 | O22: =Table1[[#This Row],[name]] -> Télépathie
A23: 2024-10-01T16:53:31.564Z | B23: 2024-10-01T16:53:31.564Z | C23: 2024-10-01T16:53:31.564Z | D23: Poison (Contrôle Mental) | E23: Poison (Mind Controlling) | F23: La victime doit accomplir une action spécifique en réponse à un déclencheur spécifique. Lancez un d100 pour déterminer l'action. | H23: <table class="table table-light table-striped table-sm og-dt"> <thead> <tr> <th scope="col" class="text-center w-15">d100</th> <th>Action</th> </tr> </thead> <tbody> <tr> <td scope="col" class="text-center w-15">01&mdash;20</td> <td>Se couche pendant une minute les yeux fermés lorsqu'on lui demande.</td> </tr> <tr> <td scope="col" class="text-center w-15">21&mdash;40</td> <td>Fuit dans la terreur pendant une minute lorsqu'elle est menacée.</td> </tr> <tr> <td scope="col" class="text-center w-15">41&mdash;60</td> <td>Répond aux questions honnàêtement pendant une minute.</td> </tr> <tr> <td scope="col" class="text-center w-15">61&mdash;75</td> <td>Attaque un ami proche pendant un round lorsqu'il est à portée immédiate.</td> </tr> <tr> <td scope="col" class="text-center w-15">76&mdash;85</td> <td>Obéit à la prochaine commande verbale donnée (si elle est comprise).</td> </tr> <tr> <td scope="col" class="text-center w-15">86&mdash;95</td> <td>Pendant un jour, devient sexuellement attiré par la prochaine créature de sa propre espèce qu'il voit.</td> </tr> <tr> <td scope="col" class="text-center w-15">96&mdash;00</td> <td>Pendant une minute, se dirige vers le prochain objet rouge aperà§u au lieu de toutes les autres actions, ignorant l'autoconservation.</td> </tr> </tbody> </table> | I23: 1d6 + 2 | J23: (Cypher System Rulebook, page 394) | K23: =TRUE() -> TRUE | L23: =TRUE() -> TRUE | M23: =FALSE() -> FALSE | N23: =LEN(Table1[[#This Row],[effect]]) -> 129 | O23: =Table1[[#This Row],[name]] -> Poison (Contrôle Mental)
A24: 2024-10-01T16:53:31.190Z | B24: 2024-10-01T16:53:31.190Z | C24: 2024-10-01T16:53:31.190Z | D24: Résistance au Feu | E24: Fireproofing | F24: Un objet inanimé traité par ce cypher bénéficie d'une Armure contre les dégâts de feu égale au niveau du cypher pendant une journée. | I24: 1d6 + 4 | J24: (Cypher System Rulebook, page 388) | K24: =TRUE() -> TRUE | L24: =FALSE() -> FALSE | M24: =FALSE() -> FALSE | N24: =LEN(Table1[[#This Row],[effect]]) -> 132 | O24: =Table1[[#This Row],[name]] -> Résistance au Feu
A25: 2024-10-01T16:53:32.010Z | B25: 2024-10-01T16:53:32.010Z | C25: 2024-10-01T16:53:32.010Z | D25: Amélioration d'Arme | E25: Weapon Enhancement | F25: Modifie l'attaque d'une arme d'une manière particulière pendant dix minutes par niveau de cypher. Lancez un d100 pour la modification. | H25: <table class="table table-light table-striped table-sm og-dt"> <thead> <tr> <th scope="col" class="text-center w-15">d100</th> <th>Modification</th> </tr> </thead> <tbody> <tr> <td scope="col" class="text-center w-15">01&mdash;10</td> <td>Facilite l'attaque d'un niveau</td> </tr> <tr> <td scope="col" class="text-center w-15">11&mdash;20</td> <td>Inflige des dégâts électriques supplémentaires égaux au niveau du cypher</td> </tr> <tr> <td scope="col" class="text-center w-15">21&mdash;30</td> <td>Inflige des dégâts de froid supplémentaires égaux au niveau du cypher</td> </tr> <tr> <td scope="col" class="text-center w-15">31&mdash;40</td> <td>Inflige des dégâts de poison supplémentaires égaux au niveau du cypher</td> </tr> <tr> <td scope="col" class="text-center w-15">41&mdash;50</td> <td>Inflige des dégâts acides supplémentaires égaux au niveau du cypher</td> </tr> <tr> <td scope="col" class="text-center w-15">51&mdash;60</td> <td>Inflige des dégâts de feu supplémentaires égaux au niveau du cypher</td> </tr> <tr> <td scope="col" class="text-center w-15">61&mdash;70</td> <td>Inflige des dégâts soniques supplémentaires égaux au niveau du cypher</td> </tr> <tr> <td scope="col" class="text-center w-15">71&mdash;80</td> <td>Inflige des dégâts psychiques supplémentaires égaux au niveau du cypher</td> </tr> <tr> <td scope="col" class="text-center w-15">81&mdash;90</td> <td>Recul (sur 18&mdash;20 lors d'un jet d'attaque réussi, la cible est repoussée de 30 pieds [9 m])</td> </tr> <tr> <td scope="col" class="text-center w-15">91&mdash;95</td> <td>Immobilisation (sur 18&mdash;20 lors d'un jet d'attaque réussi, la cible ne peut pas agir lors de son prochain tour)</td> </tr> <tr> <td scope="col" class="text-center w-15">96&mdash;97</td> <td>Facilite l'attaque de deux niveaux</td> </tr> <tr> <td scope="col" class="text-center w-15">98</td> <td>Exil (sur 18&mdash;20 lors d'un jet d'attaque réussi, la cible est envoyée à un endroit aléatoire à au moins 100 miles [160 km] de distance)</td> </tr> <tr> <td scope="col" class="text-center w-15">99</td> <td>Explose, infligeant des dégâts égaux au niveau du cypher à tous ceux dans la portée immédiate</td> </tr> <tr> <td scope="col" class="text-center w-15">00</td> <td>Ciblage du cÅ“ur (sur 18&mdash;20 lors d'un jet d'attaque réussi, la cible est tuée)</td> </tr> </tbody> </table> | I25: 1d6 + 2 | J25: (Cypher System Rulebook, page 400) | K25: =TRUE() -> TRUE | L25: =TRUE() -> TRUE | M25: =FALSE() -> FALSE | N25: =LEN(Table1[[#This Row],[effect]]) -> 134 | O25: =Table1[[#This Row],[name]] -> Amélioration d'Arme
A26: 2024-10-01T16:53:30.882Z | B26: 2024-10-01T16:53:30.882Z | C26: 2024-10-01T16:53:30.882Z | D26: Meilleur Outil | E26: Best Tool | F26: Fournit un atout supplémentaire pour toute tâche utilisant un outil, màême si cela signifie dépasser la limite normale de deux atouts. | I26: 1d6 | J26: (Cypher System Rulebook, page 384) | K26: =FALSE() -> FALSE | L26: =FALSE() -> FALSE | M26: =TRUE() -> TRUE | N26: =LEN(Table1[[#This Row],[effect]]) -> 134 | O26: =Table1[[#This Row],[name]] -> Meilleur Outil
A27: 2024-10-01T16:53:31.985Z | B27: 2024-10-01T16:53:31.985Z | C27: 2024-10-01T16:53:31.985Z | D27: Traducteur Vocal | E27: Vocal Translator | F27: Pendant vingt-quatre heures par niveau de cypher, traduit tout ce que dit l'utilisateur dans une langue que tout le monde peut comprendre. | I27: 1d6 | J27: (Cypher System Rulebook, page 399) | K27: =TRUE() -> TRUE | L27: =TRUE() -> TRUE | M27: =FALSE() -> FALSE | N27: =LEN(Table1[[#This Row],[effect]]) -> 138 | O27: =Table1[[#This Row],[name]] -> Traducteur Vocal
A28: 2024-10-01T16:53:31.658Z | B28: 2024-10-01T16:53:31.658Z | C28: 2024-10-01T16:53:31.658Z | D28: Pic de Réalité | E28: Reality Spike | F28: Une fois activé, le cypher ne bouge jamais, màême s'il est activé en l'air. Une action de Puissance le délogera, mais il sera alors ruiné. | I28: 1d6 + 4 | J28: (Cypher System Rulebook, page 395) | K28: =TRUE() -> TRUE | L28: =TRUE() -> TRUE | M28: =FALSE() -> FALSE | N28: =LEN(Table1[[#This Row],[effect]]) -> 138 | O28: =Table1[[#This Row],[name]] -> Pic de Réalité
A29: 2024-10-01T16:53:31.574Z | B29: 2024-10-01T16:53:31.574Z | C29: 2024-10-01T16:53:31.574Z | D29: Poison (Perturbation Mentale) | E29: Poison (Mind Disrupting) | F29: La victime subit des dégâts d'Intellect égaux au niveau du cypher et ne peut pas agir pendant un nombre de rounds égal au niveau du cypher. | I29: 1d6 + 2 | J29: (Cypher System Rulebook, page 394) | K29: =TRUE() -> TRUE | L29: =FALSE() -> FALSE | M29: =FALSE() -> FALSE | N29: =LEN(Table1[[#This Row],[effect]]) -> 139 | O29: =Table1[[#This Row],[name]] -> Poison (Perturbation Mentale)
A30: 2024-10-01T16:53:31.584Z | B30: 2024-10-01T16:53:31.584Z | C30: 2024-10-01T16:53:31.584Z | D30: Pic de Radiation | E30: Radiation Spike | F30: Inflige une forte impulsion de radiation qui perturbe les tissus de toute créature touchée, infligeant des dégâts égaux au niveau du cypher. | I30: 1d6 + 4 | J30: (Cypher System Rulebook, page 395) | K30: =TRUE() -> TRUE | L30: =FALSE() -> FALSE | M30: =FALSE() -> FALSE | N30: =LEN(Table1[[#This Row],[effect]]) -> 140 | O30: =Table1[[#This Row],[name]] -> Pic de Radiation
A31: 2024-10-01T16:53:31.714Z | B31: 2024-10-01T16:53:31.714Z | C31: 2024-10-01T16:53:31.714Z | D31: Repousser | E31: Repel | F31: Un PNJ à portée immédiate qui est d'un niveau inférieur au cypher décide de partir, utilisant ses cinq prochains rounds pour s'éloigner rapidement. | I31: 1d6 + 1 | J31: (Cypher System Rulebook, page 396) | K31: =FALSE() -> FALSE | L31: =FALSE() -> FALSE | M31: =TRUE() -> TRUE | N31: =LEN(Table1[[#This Row],[effect]]) -> 148 | O31: =Table1[[#This Row],[name]] -> Repousser
A32: 2024-10-01T16:53:31.692Z | B32: 2024-10-01T16:53:31.692Z | C32: 2024-10-01T16:53:31.692Z | D32: Vision à Distance | E32: Remote Viewer | F32: Pendant une heure par niveau de cypher, l'utilisateur peut voir tout ce qui se passe dans les environs du cypher, quelle que soit la distance entre eux. | I32: 1d6 | J32: (Cypher System Rulebook, page 396) | K32: =TRUE() -> TRUE | L32: =FALSE() -> FALSE | M32: =FALSE() -> FALSE | N32: =LEN(Table1[[#This Row],[effect]]) -> 152 | O32: =Table1[[#This Row],[name]] -> Vision à Distance
A33: 2024-10-01T16:53:31.220Z | B33: 2024-10-01T16:53:31.220Z | C33: 2024-10-01T16:53:31.220Z | D33: Projecteur d'Ecran de Force | E33: Force Screen Projector | F33: Crée un plan immobile de force solide mesurant jusqu'à 6 m par 6 m (20 pieds par 20 pieds) pendant une heure. Le plan se conforme à l'espace disponible. | I33: 1d6 + 3 | J33: (Cypher System Rulebook, page 389) | K33: =TRUE() -> TRUE | L33: =TRUE() -> TRUE | M33: =FALSE() -> FALSE | N33: =LEN(Table1[[#This Row],[effect]]) -> 154 | O33: =Table1[[#This Row],[name]] -> Projecteur d'Ecran de Force
A34: 2024-10-01T16:53:31.511Z | B34: 2024-10-01T16:53:31.511Z | C34: 2024-10-01T16:53:31.511Z | D34: Rayon de Nullification | E34: Nullification Ray | F34: L'utilisateur peut mettre immédiatement fin à un effet en cours dans la portée longue qui est produit par un artefact, un cypher ou une capacité spéciale. | I34: 1d6 + 3 | J34: (Cypher System Rulebook, page 393) | K34: =TRUE() -> TRUE | L34: =FALSE() -> FALSE | M34: =FALSE() -> FALSE | N34: =LEN(Table1[[#This Row],[effect]]) -> 155 | O34: =Table1[[#This Row],[name]] -> Rayon de Nullification
A35: 2024-10-01T16:53:30.907Z | B35: 2024-10-01T16:53:30.907Z | C35: 2024-10-01T16:53:30.907Z | D35: Explosion de Célérité | E35: Burst Of Speed | F35: Pendant une minute, un utilisateur qui peut normalement se déplacer sur une courte distance en une action peut se déplacer sur une longue distance à la place. | I35: 1d6 | J35: (Cypher System Rulebook, page 385) | K35: =FALSE() -> FALSE | L35: =FALSE() -> FALSE | M35: =TRUE() -> TRUE | N35: =LEN(Table1[[#This Row],[effect]]) -> 159 | O35: =Table1[[#This Row],[name]] -> Explosion de Célérité
A36: 2024-10-01T16:53:31.040Z | B36: 2024-10-01T16:53:31.040Z | C36: 2024-10-01T16:53:31.040Z | D36: Détonation (Inversion Gravitationnelle) | E36: Detonation (Gravity Inversion) | F36: Projette un petit explosif physique jusqu'à longue distance qui explose, et pendant une heure, la gravité est inversée dans un rayon long autour de l'explosion. | I36: 1d6 + 1 | J36: (Cypher System Rulebook, page 387) | K36: =TRUE() -> TRUE | L36: =TRUE() -> TRUE | M36: =FALSE() -> FALSE | N36: =LEN(Table1[[#This Row],[effect]]) -> 161 | O36: =Table1[[#This Row],[name]] -> Détonation (Inversion Gravitationnelle)
A37: 2024-10-01T16:53:31.776Z | B37: 2024-10-01T16:53:31.776Z | C37: 2024-10-01T16:53:31.776Z | D37: Inducteur de Sommeil | E37: Sleep Inducer | F37: Un contact endort la victime pendant dix minutes par niveau de cypher ou jusqu'à ce qu'elle soit réveillée par une action violente ou un bruit extràêmement fort. | I37: 1d6 | J37: (Cypher System Rulebook, page 397) | K37: =TRUE() -> TRUE | L37: =FALSE() -> FALSE | M37: =FALSE() -> FALSE | N37: =LEN(Table1[[#This Row],[effect]]) -> 162 | O37: =Table1[[#This Row],[name]] -> Inducteur de Sommeil
A38: 2024-10-01T16:53:31.799Z | B38: 2024-10-01T16:53:31.799Z | C38: 2024-10-01T16:53:31.799Z | D38: Trou Sonore | E38: Sonic Hole | F38: Attire tout le son dans un rayon de longue portée dans le dispositif pendant un round par niveau de cypher. Dans la zone affectée, aucun son ne peut àêtre entendu. | I38: 1d6 + 2 | J38: (Cypher System Rulebook, page 397) | K38: =TRUE() -> TRUE | L38: =TRUE() -> TRUE | M38: =FALSE() -> FALSE | N38: =LEN(Table1[[#This Row],[effect]]) -> 163 | O38: =Table1[[#This Row],[name]] -> Trou Sonore
A39: 2024-10-01T16:53:31.213Z | B39: 2024-10-01T16:53:31.213Z | C39: 2024-10-01T16:53:31.213Z | D39: Champ de Force | E39: Force Field | F39: Pour la prochaine journée, l'utilisateur est entouré d'un puissant champ de force, lui accordant +1 à l'Armure (+2 à l'Armure si le niveau du cypher est 5 ou plus). | G39: Certains champs, boucliers et cubes de force sont transparents. D'autres sont translucides. Quelques-uns sont opaques. | I39: 1d6 | J39: (Cypher System Rulebook, page 389) | K39: =TRUE() -> TRUE | L39: =TRUE() -> TRUE | M39: =FALSE() -> FALSE | N39: =LEN(Table1[[#This Row],[effect]]) -> 166 | O39: =Table1[[#This Row],[name]] -> Champ de Force
A40: 2024-10-01T16:53:32.029Z | B40: 2024-10-01T16:53:32.029Z | C40: 2024-10-01T16:53:32.029Z | D40: Vision aux Rayons X | E40: X-Ray Viewer | F40: Permet à l'utilisateur de voir à travers jusqu'à 2 pieds (60 cm) de matériau d'un niveau inférieur à celui du cypher. L'effet dure une minute par niveau de cypher. | I40: 1d6 + 4 | J40: (Cypher System Rulebook, page 400) | K40: =TRUE() -> TRUE | L40: =FALSE() -> FALSE | M40: =FALSE() -> FALSE | N40: =LEN(Table1[[#This Row],[effect]]) -> 167 | O40: =Table1[[#This Row],[name]] -> Vision aux Rayons X
...
